Workbook
Name fn: 'DNA sequencing'!$J$20
Name Year_span: 'DNA sequencing'!$I$1

Sheet Table
A1: Technology | B1: Date range | C1: Unit | D1: Compounded average/quarter | E1: Fastest 3-year decline | G1: Log points/quarter
A2: Electricity | B2: 1892–1973 | C2: $/watt-hour | D2: =1-(Electricity!J58/Electricity!J4)^(1/(Electricity!I58-Electricity!I4)/4) -> 0.011697801 | G2: =-LN(1-D2) -> 0.011766758 | H2: =$G$7/G2 -> 53.95524 | I2: =(1-D2)^-4 -> 1.0481923
A3: Lithium batteries | B3: 1991–2024 | C3: $/watt-hour | D3: =1-('Lithium batteries'!E37/'Lithium batteries'!E4)^(1/('Lithium batteries'!C37-'Lithium batteries'!C4)/4) -> 0.035501186 | E3: ='Lithium batteries'!F1 -> 0.076129462 | G3: =-LN(1-D3) -> 0.036146676 | H3: =$G$7/G3 -> 17.563946 | I3: =(1-D3)^-4 -> 1.1555619
A4: Illumination | B4: 1800–2023 | C4: £/lumen-hour | D4: =1-(Illumination!D727/Illumination!D504)^(1/((Illumination!C727-Illumination!C504)*4)) -> 0.0092427523 | E4: =Illumination!E1 -> 0.066782094 | G4: =-LN(1-D4) -> 0.0092857315 | H4: =$G$7/G4 -> 68.371379 | I4: =(1-D4)^-4 -> 1.0378413
A5: Compute | B5: 1940–2001 | C5: $/calculation | D5: =1-(Compute!P76/Compute!P22)^(1/(Compute!N76-Compute!N22)/4) -> 0.098502965 | E5: =Compute!P5 -> 0.25071176 | G5: =-LN(1-D5) -> 0.10369853 | H5: =$G$7/G5 -> 6.1223462 | I5: =(1-D5)^-4 -> 1.514059
A6: DNA sequencing | B6: 2001–25 | C6: $/human genome | D6: =1-('DNA sequencing'!G83/Table1[[#This Row],[Cost deflated]])^(1/('DNA sequencing'!A83-Table1[[#This Row],[Date]])*365.25/4) -> 0.14155466 | E6: ='DNA sequencing'!I3 -> 0.37854054 | G6: =-LN(1-D6) -> 0.15263227 | H6: =$G$7/G6 -> 4.1595284 | I6: =(1-D6)^-4 -> 1.8414054
A7: LLM inference | B7: 2023–26 | C7: $, given benchmark score | D7: =E7 -> 0.47 | E7: 0.47 | G7: =-LN(1-D7) -> 0.63487827 | H7: =$G$7/G7 -> 1 | I7: =(1-D7)^-4 -> 12.673499
A8: Price drops expressed as compounded quarterly rates, after inflation adjustment. The fastest drop for residential electricity price is especially uncertain as it is based on rough figures for 1902 and 1907.
A10: Year | B10: t | C10: LLM inference
A11: =DATEVALUE("2021-11-18")/365.25+1900 -> 2021.8836 | B11: =A11-$A$11 -> 0 | C11: 100
A12: 2023.5 | B12: =A12-$A$11 -> 1.6163587 | C12: =$C$11*(1-47%)^(4*(A12-$A$11)) -> 1.6493911
A13: 2026.6666 | B13: =A13-$A$11 -> 4.7829587 | C13: =$C$11*(1-47%)^(4*(A13-$A$11)) -> 0.00053075187

Sheet Electricity
B2: Hersh (1999) | E2: Edison Electric Institute | I2: Combined
A3: Year | B3: Nominal | C3: Real (1982-84 $) | E3: Year | F3: Nominal | G3: Real (1982-84 $) | I3: Year | J3: Real (9182-84 $) | L3: Index
A4: 1892 | B4: 22 | C4: =B4/VLOOKUP(A4,CPI!$D$2:$E$231,2,FALSE)*100 -> 242.61138 | I4: 1892 | J4: =C4 -> 242.61138 | K4: =I4-$I$4 -> 0 | L4: =J4/$J$4*100 -> 100
A5: 1897 | B5: 19.8 | C5: =B5/VLOOKUP(A5,CPI!$D$2:$E$231,2,FALSE)*100 -> 238.00938 | I5: 1897 | J5: =C5 -> 238.00938 | K5: =I5-$I$4 -> 5 | L5: =J5/$J$4*100 -> 98.103137
A6: 1902 | B6: 16.2 | C6: =B6/VLOOKUP(A6,CPI!$D$2:$E$231,2,FALSE)*100 -> 189.05357 | I6: 1902 | J6: =C6 -> 189.05357 | K6: =I6-$I$4 -> 10 | L6: =J6/$J$4*100 -> 77.924442
A7: 1907 | B7: 10.5 | C7: =B7/VLOOKUP(A7,CPI!$D$2:$E$231,2,FALSE)*100 -> 111.69025 | I7: 1907 | J7: =C7 -> 111.69025 | K7: =I7-$I$4 -> 15 | L7: =J7/$J$4*100 -> 46.036689
A8: 1912 | B8: 9.1 | C8: =B8/VLOOKUP(A8,CPI!$D$2:$E$231,2,FALSE)*100 -> 93.486747 | I8: 1912 | J8: =C8 -> 93.486747 | K8: =I8-$I$4 -> 20 | L8: =J8/$J$4*100 -> 38.533538
A9: 1917 | B9: 7.52 | C9: =B9/VLOOKUP(A9,CPI!$D$2:$E$231,2,FALSE)*100 -> 58.75 | I9: 1917 | J9: =C9 -> 58.75 | K9: =I9-$I$4 -> 25 | L9: =J9/$J$4*100 -> 24.215682
A10: 1922 | B10: 7.38 | C10: =B10/VLOOKUP(A10,CPI!$D$2:$E$231,2,FALSE)*100 -> 43.928571 | I10: 1922 | J10: =C10 -> 43.928571 | K10: =I10-$I$4 -> 30 | L10: =J10/$J$4*100 -> 18.106558
A11: 1927 | B11: 6.82 | C11: =B11/VLOOKUP(A11,CPI!$D$2:$E$231,2,FALSE)*100 -> 39.195402 | E11: 1926 | F11: 7 | G11: =F11/VLOOKUP(E11,CPI!$D$2:$E$231,2,FALSE)*100 -> 39.548023 | I11: 1926 | J11: =G11 -> 39.548023 | K11: =I11-$I$4 -> 34 | L11: =J11/$J$4*100 -> 16.300976
A12: 1932 | B12: 5.6 | C12: =B12/VLOOKUP(A12,CPI!$D$2:$E$231,2,FALSE)*100 -> 40.875912 | E12: 1927 | F12: 6.82 | G12: =F12/VLOOKUP(E12,CPI!$D$2:$E$231,2,FALSE)*100 -> 39.195402 | I12: 1927 | J12: =G12 -> 39.195402 | K12: =I12-$I$4 -> 35 | L12: =J12/$J$4*100 -> 16.155632
A13: 1937 | B13: 4.3 | C13: =B13/VLOOKUP(A13,CPI!$D$2:$E$231,2,FALSE)*100 -> 29.861111 | E13: 1928 | F13: 6.63 | G13: =F13/VLOOKUP(E13,CPI!$D$2:$E$231,2,FALSE)*100 -> 38.77193 | I13: 1928 | J13: =G13 -> 38.77193 | K13: =I13-$I$4 -> 36 | L13: =J13/$J$4*100 -> 15.981085
A14: 1940 | B14: 3.84 | C14: =B14/VLOOKUP(A14,CPI!$D$2:$E$231,2,FALSE)*100 -> 27.428571 | E14: 1929 | F14: 6.33 | G14: =F14/VLOOKUP(E14,CPI!$D$2:$E$231,2,FALSE)*100 -> 37.017544 | I14: 1929 | J14: =G14 -> 37.017544 | K14: =I14-$I$4 -> 37 | L14: =J14/$J$4*100 -> 15.257959
A15: 1947 | B15: 3.09 | C15: =B15/VLOOKUP(A15,CPI!$D$2:$E$231,2,FALSE)*100 -> 13.856502 | E15: 1930 | F15: 6.03 | G15: =F15/VLOOKUP(E15,CPI!$D$2:$E$231,2,FALSE)*100 -> 36.107784 | I15: 1930 | J15: =G15 -> 36.107784 | K15: =I15-$I$4 -> 38 | L15: =J15/$J$4*100 -> 14.882972
A16: 1952 | B16: 2.77 | C16: =B16/VLOOKUP(A16,CPI!$D$2:$E$231,2,FALSE)*100 -> 10.45283 | E16: 1931 | F16: 5.78 | G16: =F16/VLOOKUP(E16,CPI!$D$2:$E$231,2,FALSE)*100 -> 38.026316 | I16: 1931 | J16: =G16 -> 38.026316 | K16: =I16-$I$4 -> 39 | L16: =J16/$J$4*100 -> 15.673756
A17: 1956 | B17: 2.61 | C17: =B17/VLOOKUP(A17,CPI!$D$2:$E$231,2,FALSE)*100 -> 9.5955882 | E17: 1932 | F17: 5.61 | G17: =F17/VLOOKUP(E17,CPI!$D$2:$E$231,2,FALSE)*100 -> 40.948905 | I17: 1932 | J17: =G17 -> 40.948905 | K17: =I17-$I$4 -> 40 | L17: =J17/$J$4*100 -> 16.878394
A18: 1962 | B18: 2.41 | C18: =B18/VLOOKUP(A18,CPI!$D$2:$E$231,2,FALSE)*100 -> 7.9801325 | E18: 1933 | F18: 5.52 | G18: =F18/VLOOKUP(E18,CPI!$D$2:$E$231,2,FALSE)*100 -> 42.461538 | I18: 1933 | J18: =G18 -> 42.461538 | K18: =I18-$I$4 -> 41 | L18: =J18/$J$4*100 -> 17.501874
A19: 1963 | B19: 2.37 | C19: =B19/VLOOKUP(A19,CPI!$D$2:$E$231,2,FALSE)*100 -> 7.745098 | E19: 1934 | F19: 5.33 | G19: =F19/VLOOKUP(E19,CPI!$D$2:$E$231,2,FALSE)*100 -> 39.776119 | I19: 1934 | J19: =G19 -> 39.776119 | K19: =I19-$I$4 -> 42 | L19: =J19/$J$4*100 -> 16.394993
A20: 1964 | B20: 2.31 | C20: =B20/VLOOKUP(A20,CPI!$D$2:$E$231,2,FALSE)*100 -> 7.4516129 | E20: 1935 | F20: 5.01 | G20: =F20/VLOOKUP(E20,CPI!$D$2:$E$231,2,FALSE)*100 -> 36.569343 | I20: 1935 | J20: =G20 -> 36.569343 | K20: =I20-$I$4 -> 43 | L20: =J20/$J$4*100 -> 15.073218
A21: 1965 | B21: 2.25 | C21: =B21/VLOOKUP(A21,CPI!$D$2:$E$231,2,FALSE)*100 -> 7.1428571 | E21: 1936 | F21: 4.67 | G21: =F21/VLOOKUP(E21,CPI!$D$2:$E$231,2,FALSE)*100 -> 33.597122 | I21: 1936 | J21: =G21 -> 33.597122 | K21: =I21-$I$4 -> 44 | L21: =J21/$J$4*100 -> 13.848123
A22: 1966 | B22: 2.2 | C22: =B22/VLOOKUP(A22,CPI!$D$2:$E$231,2,FALSE)*100 -> 6.7901235 | E22: 1937 | F22: 4.29 | G22: =F22/VLOOKUP(E22,CPI!$D$2:$E$231,2,FALSE)*100 -> 29.791667 | I22: 1937 | J22: =G22 -> 29.791667 | K22: =I22-$I$4 -> 45 | L22: =J22/$J$4*100 -> 12.279583
... A31: 1975 | B31: 3.21 | C31: =B31/VLOOKUP(A31,CPI!$D$2:$E$231,2,FALSE)*100 -> 5.9665428 | E31: 1946 | F31: 3.22 | G31: =F31/VLOOKUP(E31,CPI!$D$2:$E$231,2,FALSE)*100 -> 16.512821 | I31: 1946 | J31: =G31 -> 16.512821 | K31: =I31-$I$4 -> 54 | L31: =J31/$J$4*100 -> 6.8062844
A32: 1976 | B32: 3.45 | C32: =B32/VLOOKUP(A32,CPI!$D$2:$E$231,2,FALSE)*100 -> 6.0632689 | E32: 1947 | F32: 3.09 | G32: =F32/VLOOKUP(E32,CPI!$D$2:$E$231,2,FALSE)*100 -> 13.856502 | I32: 1947 | J32: =G32 -> 13.856502 | K32: =I32-$I$4 -> 55 | L32: =J32/$J$4*100 -> 5.7113983 | U32: Richard Hersh, Power loss : the origins of deregulation and restructuring in the American electric utility system
A33: 1977 | B33: 3.78 | C33: =B33/VLOOKUP(A33,CPI!$D$2:$E$231,2,FALSE)*100 -> 6.2376238 | E33: 1948 | F33: 3.01 | G33: =F33/VLOOKUP(E33,CPI!$D$2:$E$231,2,FALSE)*100 -> 12.489627 | I33: 1948 | J33: =G33 -> 12.489627 | K33: =I33-$I$4 -> 56 | L33: =J33/$J$4*100 -> 5.147997 | U33: https://archive.org/details/powerlossorigins0000hirs/page/48/mode/2up
A34: 1978 | B34: 4.03 | C34: =B34/VLOOKUP(A34,CPI!$D$2:$E$231,2,FALSE)*100 -> 6.1809816 | E34: 1949 | F34: 2.95 | G34: =F34/VLOOKUP(E34,CPI!$D$2:$E$231,2,FALSE)*100 -> 12.394958 | I34: 1949 | J34: =G34 -> 12.394958 | K34: =I34-$I$4 -> 57 | L34: =J34/$J$4*100 -> 5.1089763 | U34: Nominal prices received from Richard Hersh, Virginia Tech, September 11, 2026.
A35: 1979 | B35: 4.43 | C35: =B35/VLOOKUP(A35,CPI!$D$2:$E$231,2,FALSE)*100 -> 6.1019284 | E35: 1950 | F35: 2.88 | G35: =F35/VLOOKUP(E35,CPI!$D$2:$E$231,2,FALSE)*100 -> 11.950207 | I35: 1950 | J35: =G35 -> 11.950207 | K35: =I35-$I$4 -> 58 | L35: =J35/$J$4*100 -> 4.9256582
A36: 1980 | B36: 5.12 | C36: =B36/VLOOKUP(A36,CPI!$D$2:$E$231,2,FALSE)*100 -> 6.2135922 | E36: 1951 | F36: 2.81 | G36: =F36/VLOOKUP(E36,CPI!$D$2:$E$231,2,FALSE)*100 -> 10.807692 | I36: 1951 | J36: =G36 -> 10.807692 | K36: =I36-$I$4 -> 59 | L36: =J36/$J$4*100 -> 4.4547343
A37: 1981 | B37: 5.86 | C37: =B37/VLOOKUP(A37,CPI!$D$2:$E$231,2,FALSE)*100 -> 6.4466447 | E37: 1952 | F37: 2.77 | G37: =F37/VLOOKUP(E37,CPI!$D$2:$E$231,2,FALSE)*100 -> 10.45283 | I37: 1952 | J37: =G37 -> 10.45283 | K37: =I37-$I$4 -> 60 | L37: =J37/$J$4*100 -> 4.3084666
A38: 1982 | B38: 6.44 | C38: =B38/VLOOKUP(A38,CPI!$D$2:$E$231,2,FALSE)*100 -> 6.6735751 | E38: 1953 | F38: 2.74 | G38: =F38/VLOOKUP(E38,CPI!$D$2:$E$231,2,FALSE)*100 -> 10.262172 | I38: 1953 | J38: =G38 -> 10.262172 | K38: =I38-$I$4 -> 61 | L38: =J38/$J$4*100 -> 4.2298808
A39: 1983 | B39: 6.83 | C39: =B39/VLOOKUP(A39,CPI!$D$2:$E$231,2,FALSE)*100 -> 6.8574297 | E39: 1954 | F39: 2.69 | G39: =F39/VLOOKUP(E39,CPI!$D$2:$E$231,2,FALSE)*100 -> 10 | I39: 1954 | J39: =G39 -> 10 | K39: =I39-$I$4 -> 62 | L39: =J39/$J$4*100 -> 4.1218182
A40: 1984 | B40: 7.17 | C40: =B40/VLOOKUP(A40,CPI!$D$2:$E$231,2,FALSE)*100 -> 6.9008662 | E40: 1955 | F40: 2.64 | G40: =F40/VLOOKUP(E40,CPI!$D$2:$E$231,2,FALSE)*100 -> 9.8507463 | I40: 1955 | J40: =G40 -> 9.8507463 | K40: =I40-$I$4 -> 63 | L40: =J40/$J$4*100 -> 4.0602985
A41: 1985 | B41: 7.39 | C41: =B41/VLOOKUP(A41,CPI!$D$2:$E$231,2,FALSE)*100 -> 6.8680297 | E41: 1956 | F41: 2.6 | G41: =F41/VLOOKUP(E41,CPI!$D$2:$E$231,2,FALSE)*100 -> 9.5588235 | I41: 1956 | J41: =G41 -> 9.5588235 | K41: =I41-$I$4 -> 64 | L41: =J41/$J$4*100 -> 3.9399733
A42: 1986 | B42: 7.43 | C42: =B42/VLOOKUP(A42,CPI!$D$2:$E$231,2,FALSE)*100 -> 6.7791971 | E42: 1957 | F42: 2.56 | G42: =F42/VLOOKUP(E42,CPI!$D$2:$E$231,2,FALSE)*100 -> 9.1103203 | I42: 1957 | J42: =G42 -> 9.1103203 | K42: =I42-$I$4 -> 65 | L42: =J42/$J$4*100 -> 3.7551084
A43: 1987 | B43: 7.45 | C43: =B43/VLOOKUP(A43,CPI!$D$2:$E$231,2,FALSE)*100 -> 6.5580986 | E43: 1958 | F43: 2.53 | G43: =F43/VLOOKUP(E43,CPI!$D$2:$E$231,2,FALSE)*100 -> 8.7543253 | I43: 1958 | J43: =G43 -> 8.7543253 | K43: =I43-$I$4 -> 66 | L43: =J43/$J$4*100 -> 3.6083737
A44: 1988 | B44: 7.49 | C44: =B44/VLOOKUP(A44,CPI!$D$2:$E$231,2,FALSE)*100 -> 6.3313609 | E44: 1959 | F44: 2.5 | G44: =F44/VLOOKUP(E44,CPI!$D$2:$E$231,2,FALSE)*100 -> 8.5910653 | I44: 1959 | J44: =G44 -> 8.5910653 | K44: =I44-$I$4 -> 67 | L44: =J44/$J$4*100 -> 3.5410809
A45: 1989 | B45: 7.65 | C45: =B45/VLOOKUP(A45,CPI!$D$2:$E$231,2,FALSE)*100 -> 6.1693548 | E45: 1960 | F45: 2.47 | G45: =F45/VLOOKUP(E45,CPI!$D$2:$E$231,2,FALSE)*100 -> 8.3445946 | I45: 1960 | J45: =G45 -> 8.3445946 | K45: =I45-$I$4 -> 68 | L45: =J45/$J$4*100 -> 3.4394902
A46: 1990 | B46: 7.83 | C46: =B46/VLOOKUP(A46,CPI!$D$2:$E$231,2,FALSE)*100 -> 5.9908187 | E46: 1961 | F46: 2.45 | G46: =F46/VLOOKUP(E46,CPI!$D$2:$E$231,2,FALSE)*100 -> 8.1939799 | I46: 1961 | J46: =G46 -> 8.1939799 | K46: =I46-$I$4 -> 69 | L46: =J46/$J$4*100 -> 3.3774095
... A58: 2002 | B58: 8.46 | C58: =B58/VLOOKUP(A58,CPI!$D$2:$E$231,2,FALSE)*100 -> 4.7026126 | E58: 1973 | F58: 2.38 | G58: =F58/VLOOKUP(E58,CPI!$D$2:$E$231,2,FALSE)*100 -> 5.3603604 | I58: 1973 | J58: =G58 -> 5.3603604 | K58: =I58-$I$4 -> 81 | L58: =J58/$J$4*100 -> 2.2094431
A59: 2003 | B59: 8.7 | C59: =B59/VLOOKUP(A59,CPI!$D$2:$E$231,2,FALSE)*100 -> 4.7282609
A60: 2004 | B60: 8.95 | C60: =B60/VLOOKUP(A60,CPI!$D$2:$E$231,2,FALSE)*100 -> #N/A
...

Sheet Illumination
D1: Max 3-year decline rate | E1: {=1-EXP(LN(MIN(D7:D727/D4:D724))/12)} -> 0.066782094 | F1: /quarter
A3: Entity | B3: Code | C3: Year | D3: Price of lighting (average)
A4: United Kingdom | B4: GBR | C4: 1300 | D4: 29674.293
A5: United Kingdom | B5: GBR | C5: 1301 | D5: 30558.924
A6: United Kingdom | B6: GBR | C6: 1302 | D6: 31341.666
A7: United Kingdom | B7: GBR | C7: 1303 | D7: 32197.186
A8: United Kingdom | B8: GBR | C8: 1304 | D8: 33004.742
A9: United Kingdom | B9: GBR | C9: 1305 | D9: 33554.906
A10: United Kingdom | B10: GBR | C10: 1306 | D10: 33659.79
A11: United Kingdom | B11: GBR | C11: 1307 | D11: 33764.492
A12: United Kingdom | B12: GBR | C12: 1308 | D12: 33118.44
A13: United Kingdom | B13: GBR | C13: 1309 | D13: 31314.613
A14: United Kingdom | B14: GBR | C14: 1310 | D14: 29988.13
A15: United Kingdom | B15: GBR | C15: 1311 | D15: 28459.63
... A503: United Kingdom | B503: GBR | C503: 1799 | D503: 8989.283
A504: United Kingdom | B504: GBR | C504: 1800 | D504: 8497.482 | E504: =1-(D505/D504)^(1/3) -> 0.010079345
A505: United Kingdom | B505: GBR | C505: 1801 | D505: 8243.116 | E505: =1-(D506/D505)^(1/3) -> 0.00066106897
A506: United Kingdom | B506: GBR | C506: 1802 | D506: 8226.779 | E506: =1-(D507/D506)^(1/3) -> 0.0021600422
A507: United Kingdom | B507: GBR | C507: 1803 | D507: 8173.5835 | E507: =1-(D508/D507)^(1/3) -> -0.00039362581
A508: United Kingdom | B508: GBR | C508: 1804 | D508: 8183.2393 | E508: =1-(D509/D508)^(1/3) -> -0.0054642727
A509: United Kingdom | B509: GBR | C509: 1805 | D509: 8318.12 | E509: =1-(D510/D509)^(1/3) -> 0.00019711864
A510: United Kingdom | B510: GBR | C510: 1806 | D510: 8313.202 | E510: =1-(D511/D510)^(1/3) -> 0.0066442853
A511: United Kingdom | B511: GBR | C511: 1807 | D511: 8148.5947 | E511: =1-(D512/D511)^(1/3) -> -0.009800368
A512: United Kingdom | B512: GBR | C512: 1808 | D512: 8390.528 | E512: =1-(D513/D512)^(1/3) -> 0.0039936274
A513: United Kingdom | B513: GBR | C513: 1809 | D513: 8290.403 | E513: =1-(D514/D513)^(1/3) -> -0.00042259938
A514: United Kingdom | B514: GBR | C514: 1810 | D514: 8300.918 | E514: =1-(D515/D514)^(1/3) -> -0.0058163014
A515: United Kingdom | B515: GBR | C515: 1811 | D515: 8446.604 | E515: =1-(D516/D515)^(1/3) -> 0.0074757714
... A603: United Kingdom | B603: GBR | C603: 1899 | D603: 225.08331 | E603: =1-(D604/D603)^(1/3) -> 0.0036347135
A604: United Kingdom | B604: GBR | C604: 1900 | D604: 222.63788 | E604: =1-(D605/D604)^(1/3) -> -0.00070129042 | F604: =D604/$D$604*100 -> 100
A605: United Kingdom | B605: GBR | C605: 1901 | D605: 223.10661 | E605: =1-(D606/D605)^(1/3) -> -0.015892989 | F605: =D605/$D$604*100 -> 100.21053
A606: United Kingdom | B606: GBR | C606: 1902 | D606: 233.91406 | E606: =1-(D607/D606)^(1/3) -> -0.0038155477 | F606: =D606/$D$604*100 -> 105.06481
A607: United Kingdom | B607: GBR | C607: 1903 | D607: 236.60182 | E607: =1-(D608/D607)^(1/3) -> 0.0020020459 | F607: =D607/$D$604*100 -> 106.27204
A608: United Kingdom | B608: GBR | C608: 1904 | D608: 235.1836 | E608: =1-(D609/D608)^(1/3) -> 0.0094639453 | F608: =D608/$D$604*100 -> 105.63503
A609: United Kingdom | B609: GBR | C609: 1905 | D609: 228.5693 | E609: =1-(D610/D609)^(1/3) -> 0.0022648341 | F609: =D609/$D$604*100 -> 102.66416
A610: United Kingdom | B610: GBR | C610: 1906 | D610: 227.0198 | E610: =1-(D611/D610)^(1/3) -> 0.0013520766 | F610: =D610/$D$604*100 -> 101.96818
A611: United Kingdom | B611: GBR | C611: 1907 | D611: 226.1002 | E611: =1-(D612/D611)^(1/3) -> 0.00031032748 | F611: =D611/$D$604*100 -> 101.55514
A612: United Kingdom | B612: GBR | C612: 1908 | D612: 225.88977 | E612: =1-(D613/D612)^(1/3) -> -0.0017556645 | F612: =D612/$D$604*100 -> 101.46062
A613: United Kingdom | B613: GBR | C613: 1909 | D613: 227.08162 | E613: =1-(D614/D613)^(1/3) -> -0.0089173906 | F613: =D613/$D$604*100 -> 101.99595
A614: United Kingdom | B614: GBR | C614: 1910 | D614: 233.21088 | E614: =1-(D615/D614)^(1/3) -> 0.001467923 | F614: =D614/$D$604*100 -> 104.74897
A615: United Kingdom | B615: GBR | C615: 1911 | D615: 232.18538 | E615: =1-(D616/D615)^(1/3) -> 0.011904867 | F615: =D615/$D$604*100 -> 104.28835
...

Sheet Lithium batteries
E1: Max 3-year decline rate | F1: {=1-EXP(LN(MIN(E7:E37/E4:E34))/12)} -> 0.076129462 | G1: /quarter
A3: Entity | B3: Code | C3: Year | D3: t | E3: Price of lithium-ion battery cells | F3: Index
A4: World | B4: OWID_WRL | C4: 1991 | D4: =C4-$C$4 -> 0 | E4: 9210.23 | F4: =Table3[[#This Row],[Price of lithium-ion battery cells]]/$E$4*100 -> 100
A5: World | B5: OWID_WRL | C5: 1992 | D5: =C5-$C$4 -> 1 | E5: 7388.138 | F5: =Table3[[#This Row],[Price of lithium-ion battery cells]]/$E$4*100 -> 80.21665
A6: World | B6: OWID_WRL | C6: 1993 | D6: =C6-$C$4 -> 2 | E6: 5881.7812 | F6: =Table3[[#This Row],[Price of lithium-ion battery cells]]/$E$4*100 -> 63.861393
A7: World | B7: OWID_WRL | C7: 1994 | D7: =C7-$C$4 -> 3 | E7: 6714.4497 | F7: =Table3[[#This Row],[Price of lithium-ion battery cells]]/$E$4*100 -> 72.902085
A8: World | B8: OWID_WRL | C8: 1995 | D8: =C8-$C$4 -> 4 | E8: 6301.8833 | F8: =Table3[[#This Row],[Price of lithium-ion battery cells]]/$E$4*100 -> 68.422649
A9: World | B9: OWID_WRL | C9: 1996 | D9: =C9-$C$4 -> 5 | E9: 5307.834 | F9: =Table3[[#This Row],[Price of lithium-ion battery cells]]/$E$4*100 -> 57.629766
A10: World | B10: OWID_WRL | C10: 1997 | D10: =C10-$C$4 -> 6 | E10: 4545.2925 | F10: =Table3[[#This Row],[Price of lithium-ion battery cells]]/$E$4*100 -> 49.350478
A11: World | B11: OWID_WRL | C11: 1998 | D11: =C11-$C$4 -> 7 | E11: 3656.8633 | F11: =Table3[[#This Row],[Price of lithium-ion battery cells]]/$E$4*100 -> 39.704365
A12: World | B12: OWID_WRL | C12: 1999 | D12: =C12-$C$4 -> 8 | E12: 2769.8726 | F12: =Table3[[#This Row],[Price of lithium-ion battery cells]]/$E$4*100 -> 30.07387
A13: World | B13: OWID_WRL | C13: 2000 | D13: =C13-$C$4 -> 9 | E13: 2690.6272 | F13: =Table3[[#This Row],[Price of lithium-ion battery cells]]/$E$4*100 -> 29.213464
A14: World | B14: OWID_WRL | C14: 2001 | D14: =C14-$C$4 -> 10 | E14: 1878.0293 | F14: =Table3[[#This Row],[Price of lithium-ion battery cells]]/$E$4*100 -> 20.390688
A15: World | B15: OWID_WRL | C15: 2002 | D15: =C15-$C$4 -> 11 | E15: 1345.5295 | F15: =Table3[[#This Row],[Price of lithium-ion battery cells]]/$E$4*100 -> 14.609076
... A37: World | B37: OWID_WRL | C37: 2024 | D37: =C37-$C$4 -> 33 | E37: 78 | F37: =Table3[[#This Row],[Price of lithium-ion battery cells]]/$E$4*100 -> 0.84688439

Sheet Compute
E4: Megabytes | I4: Total cost per
D5: Multiplicati | E5: of rapid | F5: Cycle | H5: Capital cost | I5: million | J5: Labor cost of | N5: Max 3-year decline rate | P5: {=1-EXP(LN(MIN(P23:P76/P20:P73))/12)} -> 0.25071176
C6: Additions | D6: ons per | E6: access | F6: Speed | G6: Computing | H6: (current | I6: calculations | J6: computation | P6: {=1-EXP(LN(MIN(P23:P76/P20:P73))/3)} -> 0.68479313
A7: Date | B7: Device | C7: per second | D7: second | E7: memory | F7: (Khz) | G7: Power (MIPS-E) | H7: dollars, 000s) | I7: (1998 $) | J7: (hours per inst)
M8: t | N8: Year | O8: Annual min | P8: Cumulative min
A9: 1880 | B9: Manual calculations | C9: 0.07 | D9: 0.00318 | E9: 1.5e-05 | F9: na | G9: 1.68e-08 | H9: 0.00181 | I9: 56832.568 | J9: 0.0165 | K9: L | N9: {=_xlfn.GROUPBY(A9:A115,I9:I115,_xleta.MIN)} -> 1857 | O9: 39923.748 | P9: =MIN($O$9:O9) -> 39923.748 | Q9: =P9/$P$14*100 -> 1001.8387
A10: 1857 | B10: Scheutz Difference Engine | C10: 0.2 | D10: 0.02 | E10: 3.45e-05 | F10: na | G10: 1.34e-07 | H10: 87.2 | I10: 39923.748 | J10: 0.0229 | K10: M | N10: 1874 | O10: 39722.836 | P10: =MIN($O$9:O10) -> 39722.836 | Q10: =P10/$P$14*100 -> 996.79705
A11: 1874 | B11: Original Odhner | C11: 0.07 | D11: 0.00318 | E11: 1.84e-05 | F11: na | G11: 1.87e-08 | H11: 2.62 | I11: 39722.836 | J11: 0.0184 | K11: M | N11: 1880 | O11: 56832.568 | P11: =MIN($O$9:O11) -> 39722.836 | Q11: =P11/$P$14*100 -> 996.79705
A12: 1890 | B12: Hollerith Tabulator | C12: 0.53 | D12: 0.0053 | E12: 0.000288 | F12: na | G12: 3.13e-07 | H12: 362 | I12: 79397.789 | J12: 0.0231 | K12: M | N12: 1890 | O12: 79397.789 | P12: =MIN($O$9:O12) -> 39722.836 | Q12: =P12/$P$14*100 -> 996.79705
A13: 1895 | B13: Steiger Millionaire | C13: 0.5 | D13: 0.05 | E13: 2.3e-05 | F13: na | G13: 2.59e-07 | H13: 6.68 | I13: 3985.0475 | J13: 0.00167 | K13: M | N13: 1895 | O13: 3985.0475 | P13: =MIN($O$9:O13) -> 3985.0475 | Q13: =P13/$P$14*100 -> 100
A14: 1902 | B14: Automatic Tabulator | C14: 2.5 | D14: 0.025 | E14: 0.000288 | F14: naa | G14: 1.48e-06 | H14: 564 | I14: 23482.868 | J14: 0.00961 | K14: M | N14: 1902 | O14: 23482.868 | P14: =MIN($O$9:O14) -> 3985.0475 | Q14: =P14/$P$14*100 -> 100
A15: 1905 | B15: Burroughs Model 9 | C15: 0.3 | D15: 0.01 | E15: 2.07e-05 | F15: na | G15: 6.72e-08 | H15: 4.2 | I15: 16175.047 | J15: 0.00526 | K15: M | N15: 1905 | O15: 16175.047 | P15: =MIN($O$9:O15) -> 3985.0475 | Q15: =P15/$P$14*100 -> 100
A16: 1907 | B16: Adding Tabulator | C16: 2.5 | D16: 0.05 | E16: 2.3e-05 | F16: na | G16: 3.87e-07 | H16: 174 | I16: 27204.78 | J16: 0.00917 | K16: M | N16: 1907 | O16: 27204.78 | P16: =MIN($O$9:O16) -> 3985.0475 | Q16: =P16/$P$14*100 -> 100
A17: 1911 | B17: Monroe Calculator | C17: 0.0333 | D17: 0.01 | E17: 2.4e-05 | F17: na | G17: 2.91e-08 | H17: 0.611 | I17: 67695.792 | J17: 0.0194 | K17: M | N17: 1911 | O17: 67695.792 | P17: =MIN($O$9:O17) -> 3985.0475 | Q17: =P17/$P$14*100 -> 100
A18: 1919 | B18: IBM Tabulator | C18: 0.2 | D18: 0.005 | E18: 4e-05 | F18: na | G18: 5.33e-08 | H18: 189 | I18: 239752.41 | J18: 0.0579 | K18: M | N18: 1919 | O18: 239752.41 | P18: =MIN($O$9:O18) -> 3985.0475 | Q18: =P18/$P$14*100 -> 100
A19: 1935 | B19: IBM 601 | C19: na | D19: na | E19: na | F19: na | G19: 1e-06 | H19: 654 | I19: 50853.619 | J19: 0.00778 | K19: M | N19: 1935 | O19: 50853.619 | P19: =MIN($O$9:O19) -> 3985.0475 | Q19: =P19/$P$14*100 -> 100
A20: 1938 | B20: Zuse-1 | C20: 0.1 | D20: 0.01 | E20: 3.05e-05 | F20: na | G20: 4.45e-08 | H20: 116 | I20: 479116.04 | J20: 0.0714 | K20: M | N20: 1938 | O20: 479116.04 | P20: =MIN($O$9:O20) -> 3985.0475 | Q20: =P20/$P$14*100 -> 100
A21: 1939 | B21: Zuse-2 | C21: 1 | D21: 0.1 | E21: 3.05e-05 | F21: na | G21: 4.45e-07 | H21: 117 | I21: 49150.28 | J21: 0.00711 | K21: V | N21: 1939 | O21: 24137.68 | P21: =MIN($O$9:O21) -> 3985.0475 | Q21: =P21/$P$14*100 -> 100
A22: 1939 | B22: BTL Model 1 | C22: 3.33 | D22: 3.33 | E22: 3.81e-06 | F22: na | G22: 1.99e-06 | H22: 587 | I22: 24137.68 | J22: 0.00349 | K22: V | M22: =N22-$N$22 -> 0 | N22: 1940 | O22: 8670.3135 | P22: =MIN($O$9:O22) -> 3985.0475 | Q22: =P22/$P$14*100 -> 100
A23: 1940 | B23: Bell Calculator Model 1 | C23: na | D23: na | E23: na | F23: na | G23: 3.33e-06 | H23: 233 | I23: 8670.3135 | J23: 0.00121 | K23: V | M23: =N23-$N$22 -> 1 | N23: 1941 | O23: 25542.674 | P23: =MIN($O$9:O23) -> 3985.0475 | Q23: =P23/$P$14*100 -> 100
A24: 1941 | B24: Zuse-3 | C24: 1.7 | D24: 0.3 | E24: 0.000244 | F24: 0.0053 | G24: 1.34e-06 | H24: 313 | I24: 25542.674 | J24: 0.00338 | K24: V | M24: =N24-$N$22 -> 2 | N24: 1942 | O24: 1399.3684 | P24: =MIN($O$9:O24) -> 1399.3684 | Q24: =P24/$P$14*100 -> 35.115476
A25: 1942 | B25: Harvard Mark I | C25: 3.3 | D25: 0.17 | E25: 0.000275 | F25: 0.0033 | G25: 2.03e-06 | H25: 2000 | I25: 59651.266 | J25: 0.00851 | K25: V | M25: =N25-$N$22 -> 3 | N25: 1943 | O25: 310.9659 | P25: =MIN($O$9:O25) -> 310.9659 | Q25: =P25/$P$14*100 -> 7.8033173
A26: 1942 | B26: Atanasoff Berry Computer | C26: 30 | D26: 0.5 | E26: 0.000229 | F26: 0.06 | G26: 6.96e-06 | H26: 70.1 | I26: 1399.3684 | J26: 0.0002 | K26: V | M26: =N26-$N$22 -> 4 | N26: 1944 | O26: 160295.88 | P26: =MIN($O$9:O26) -> 310.9659 | Q26: =P26/$P$14*100 -> 7.8033173
A27: 1943 | B27: BTL Model 2 | C27: 3.33 | D27: 0.2 | E27: 1.19e-05 | F27: na | G27: 1.1e-06 | H27: 472 | I27: 40815.663 | J27: 0.00482 | K27: V | M27: =N27-$N$22 -> 5 | N27: 1945 | O27: 21165.077 | P27: =MIN($O$9:O27) -> 310.9659 | Q27: =P27/$P$14*100 -> 7.8033173
A28: 1943 | B28: BTL Model 3 | C28: 3.33 | D28: 1 | E28: 4.29e-05 | F28: na | G28: 3.02e-06 | H28: 1890 | I28: 40899.011 | J28: 0.00483 | K28: V | M28: =N28-$N$22 -> 6 | N28: 1946 | O28: 184.8347 | P28: =MIN($O$9:O28) -> 184.8347 | Q28: =P28/$P$14*100 -> 4.6382057
A29: 1943 | B29: Colossus | C29: 5000 | D29: 50 | E29: 2.38e-06 | F29: na | G29: 0.000229 | H29: 943 | I29: 310.9659 | J29: 3.67e-05 | K29: V | M29: =N29-$N$22 -> 7 | N29: 1947 | O29: 35573.921 | P29: =MIN($O$9:O29) -> 184.8347 | Q29: =P29/$P$14*100 -> 4.6382057
A30: 1944 | B30: ASCC Mark 1 | C30: 3.33 | D30: 0.167 | E30: 0.000601 | F30: na | G30: 2.48e-06 | H30: 2780 | I30: 160295.88 | J30: 0.0183 | K30: V | M30: =N30-$N$22 -> 8 | N30: 1948 | O30: 474.612 | P30: =MIN($O$9:O30) -> 184.8347 | Q30: =P30/$P$14*100 -> 4.6382057
A31: 1945 | B31: Zuse-4 | C31: 2 | D31: 0.5 | E31: 0.000244 | F31: na | G31: 2.18e-06 | H31: 453 | I31: 21165.077 | J31: 0.00245 | K31: V | M31: =N31-$N$22 -> 9 | N31: 1949 | O31: 23.0498 | P31: =MIN($O$9:O31) -> 23.0498 | Q31: =P31/$P$14*100 -> 0.57840716
A32: 1946 | B32: BTL Model 5 | C32: 3.33 | D32: 1 | E32: 0.000147 | F32: na | G32: 3.51e-06 | H32: 4180 | I32: 71441.565 | J32: 0.00847 | K32: V | M32: =N32-$N$22 -> 10 | N32: 1950 | O32: 67.8124 | P32: =MIN($O$9:O32) -> 23.0498 | Q32: =P32/$P$14*100 -> 0.57840716
A33: 1946 | B33: ENIAC | C33: 5000 | D33: 333 | E33: 9.54e-05 | F33: 0.1 | G33: 0.00296 | H33: 5640 | I33: 184.8347 | J33: 2.19e-05 | K33: V | M33: =N33-$N$22 -> 11 | N33: 1951 | O33: 76.3854 | P33: =MIN($O$9:O33) -> 23.0498 | Q33: =P33/$P$14*100 -> 0.57840716
A34: 1947 | B34: Harvard Mark 2 | C34: 5 | D34: 1.43 | E34: 0.000488 | F34: na | G34: 6.65e-06 | H34: 2190 | I34: 35573.921 | J34: 0.0043 | K34: V | M34: =N34-$N$22 -> 12 | N34: 1952 | O34: 27.5938 | P34: =MIN($O$9:O34) -> 23.0498 | Q34: =P34/$P$14*100 -> 0.57840716
A35: 1948 | B35: IBM SSEC | C35: 3330 | D35: 50 | E35: 4.58e-05 | F35: na | G35: 0.000643 | H35: 3390 | I35: 474.612 | J35: 5.65e-05 | K35: V | M35: =N35-$N$22 -> 13 | N35: 1953 | O35: 4.74 | P35: =MIN($O$9:O35) -> 4.74 | Q35: =P35/$P$14*100 -> 0.11894463
A36: 1949 | B36: BINAC | C36: na | D36: na | E36: na | F36: na | G36: 0.00525 | H36: 1900 | I36: 24.8057 | J36: 2.82e-06 | K36: V | M36: =N36-$N$22 -> 14 | N36: 1954 | O36: 113.2226 | P36: =MIN($O$9:O36) -> 4.74 | Q36: =P36/$P$14*100 -> 0.11894463
A37: 1949 | B37: EDSAC | C37: 3330 | D37: 333 | E37: 0.00214 | F37: 0.5 | G37: 0.00271 | H37: 685 | I37: 23.0498 | J37: 2.62e-06 | K37: V | M37: =N37-$N$22 -> 15 | N37: 1955 | O37: 1.5888 | P37: =MIN($O$9:O37) -> 1.5888 | Q37: =P37/$P$14*100 -> 0.039869035
A38: 1950 | B38: SEAC | C38: 5000 | D38: 500 | E38: 0.00549 | F38: na | G38: 0.00481 | H38: 5420 | I38: 67.8124 | J38: 7.47e-06 | K38: V | M38: =N38-$N$22 -> 18 | N38: 1958 | O38: 67.0466 | P38: =MIN($O$9:O38) -> 1.5888 | Q38: =P38/$P$14*100 -> 0.039869035
A39: 1951 | B39: Zuse-5 I | C39: 10 | D39: 2 | E39: 0.000244 | F39: na | G39: 9.98e-06 | H39: 5840 | I39: 35076.964 | J39: 0.00382 | K39: V | M39: =N39-$N$22 -> 19 | N39: 1959 | O39: 2.8142 | P39: =MIN($O$9:O39) -> 1.5888 | Q39: =P39/$P$14*100 -> 0.039869035
A40: 1951 | B40: Univac I | C40: na | D40: na | E40: na | F40: na | G40: 0.00458 | H40: 5840 | I40: 76.3854 | J40: 8.32e-06 | K40: V | M40: =N40-$N$22 -> 20 | N40: 1960 | O40: 0.5671 | P40: =MIN($O$9:O40) -> 0.5671 | Q40: =P40/$P$14*100 -> 0.014230696
A41: 1952 | B41: IBM CPC | C41: 1250 | D41: 100 | E41: 0.000154 | F41: 50 | G41: 0.00219 | H41: 614 | I41: 27.5938 | J41: 2.92e-06 | K41: V | M41: =N41-$N$22 -> 21 | N41: 1961 | O41: 0.5212 | P41: =MIN($O$9:O41) -> 0.5212 | Q41: =P41/$P$14*100 -> 0.013078891
A42: 1953 | B42: Univac 1103 | C42: 0 | D42: 0 | E42: 0 | F42: na | G42: 0.0333 | H42: 5450 | I42: 17.3722 | J42: 1.75e-06 | K42: V | M42: =N42-$N$22 -> 22 | N42: 1962 | O42: 2.1884 | P42: =MIN($O$9:O42) -> 0.5212 | Q42: =P42/$P$14*100 -> 0.013078891
A43: 1953 | B43: IBM 650 | C43: 1430 | D43: 100 | E43: 0.00488 | F43: 125 | G43: 0.00103 | H43: 1220 | I43: 92.7589 | J43: 9.35e-06 | K43: V | M43: =N43-$N$22 -> 23 | N43: 1963 | O43: 2.9857 | P43: =MIN($O$9:O43) -> 0.5212 | Q43: =P43/$P$14*100 -> 0.013078891
...

Sheet DNA sequencing
H1: Short span | I1: 3 | J1: years
H2: Max rate: | I2: =MAX(Table1[Log points/ short span]) -> 0.47568459 | J2: log points/quarter
I3: =1-EXP(-I2) -> 0.37854054 | J3: /quarter
A5: Date | B5: Year | C5: t | D5: Cost per Mb | E5: Cost per Genome | F5: CPI | G5: Cost deflated | H5: Row for X years later | I5: Log points/ short span | J5: Index
A6: 37164 | B6: =Table1[[#This Row],[Date]]/365.25+1900 -> 2001.7495 | C6: =Table1[[#This Row],[Year]]-$B$6 -> 0 | D6: 5292.3929 | E6: 95263072 | F6: =VLOOKUP(A6+1,CPI!$A$2:$B$956,2,FALSE) -> 177.6 | G6: =E6/F6*$F$84 -> 1.7280861e+08 | H6: =_xlfn.XMATCH(Table1[[#This Row],[Date]]+1+Year_span*365.25,Table1[Date],-1,1) -> 8 | I6: {=-365.25/4*AVERAGE(LN(INDEX(Table1[Cost deflated],Table1[[#This Row],[Row for X years later]])/Table1[[#This Row],[Cost deflated]])/(INDEX(Table1[Date],Table1[[#This Row],[Row for X years later]])-Table1[[#This Row],[Date]]),LN(INDEX(Table1[Cost deflated],Table1[[#This Row],[Row for X years later]]+1)/Table1[[#This Row],[Cost deflated]])/(INDEX(Table1[Date],Table1[[#This Row],[Row for X years later]]+1)-Table1[[#This Row],[Date]]))} -> 0.14123697 | J6: =Table1[[#This Row],[Cost deflated]]/$G$6*100 -> 100
A7: 37346 | B7: =Table1[[#This Row],[Date]]/365.25+1900 -> 2002.2478 | C7: =Table1[[#This Row],[Year]]-$B$6 -> 0.49828884 | D7: 3898.6354 | E7: 70175437 | F7: =VLOOKUP(A7+1,CPI!$A$2:$B$956,2,FALSE) -> 179.3 | G7: =E7/F7*$F$84 -> 1.2609231e+08 | H7: =_xlfn.XMATCH(Table1[[#This Row],[Date]]+1+Year_span*365.25,Table1[Date],-1,1) -> 10 | I7: {=-LN(INDEX(Table1[Cost deflated],Table1[[#This Row],[Row for X years later]])/Table1[[#This Row],[Cost deflated]])/(INDEX(Table1[Date],Table1[[#This Row],[Row for X years later]])-Table1[[#This Row],[Date]])*365.25/4} -> 0.12832333 | J7: =Table1[[#This Row],[Cost deflated]]/$G$6*100 -> 72.96645
A8: 37529 | B8: =Table1[[#This Row],[Date]]/365.25+1900 -> 2002.7488 | C8: =Table1[[#This Row],[Year]]-$B$6 -> 0.99931554 | D8: 3413.8012 | E8: 61448422 | F8: =VLOOKUP(A8+1,CPI!$A$2:$B$956,2,FALSE) -> 181.2 | G8: =E8/F8*$F$84 -> 1.0925373e+08 | H8: =_xlfn.XMATCH(Table1[[#This Row],[Date]]+1+Year_span*365.25,Table1[Date],-1,1) -> 12 | I8: {=-LN(INDEX(Table1[Cost deflated],Table1[[#This Row],[Row for X years later]])/Table1[[#This Row],[Cost deflated]])/(INDEX(Table1[Date],Table1[[#This Row],[Row for X years later]])-Table1[[#This Row],[Date]])*365.25/4} -> 0.1246995 | J8: =Table1[[#This Row],[Cost deflated]]/$G$6*100 -> 63.222391
A9: 37711 | B9: =Table1[[#This Row],[Date]]/365.25+1900 -> 2003.2471 | C9: =Table1[[#This Row],[Year]]-$B$6 -> 1.4976044 | D9: 2986.2047 | E9: 53751684 | F9: =VLOOKUP(A9+1,CPI!$A$2:$B$956,2,FALSE) -> 183.2 | G9: =E9/F9*$F$84 -> 94525799 | H9: =_xlfn.XMATCH(Table1[[#This Row],[Date]]+1+Year_span*365.25,Table1[Date],-1,1) -> 14 | I9: {=-LN(INDEX(Table1[Cost deflated],Table1[[#This Row],[Row for X years later]])/Table1[[#This Row],[Cost deflated]])/(INDEX(Table1[Date],Table1[[#This Row],[Row for X years later]])-Table1[[#This Row],[Date]])*365.25/4} -> 0.13530024 | J9: =Table1[[#This Row],[Cost deflated]]/$G$6*100 -> 54.699705
A10: 37925 | B10: =Table1[[#This Row],[Date]]/365.25+1900 -> 2003.833 | C10: =Table1[[#This Row],[Year]]-$B$6 -> 2.0835044 | D10: 2230.9752 | E10: 40157554 | F10: =VLOOKUP(A10+1,CPI!$A$2:$B$956,2,FALSE) -> 185 | G10: =E10/F10*$F$84 -> 69932536 | H10: =_xlfn.XMATCH(Table1[[#This Row],[Date]]+1+Year_span*365.25,Table1[Date],-1,1) -> 17 | I10: {=-LN(INDEX(Table1[Cost deflated],Table1[[#This Row],[Row for X years later]])/Table1[[#This Row],[Cost deflated]])/(INDEX(Table1[Date],Table1[[#This Row],[Row for X years later]])-Table1[[#This Row],[Date]])*365.25/4} -> 0.11928723 | J10: =Table1[[#This Row],[Cost deflated]]/$G$6*100 -> 40.468202
A11: 38017 | B11: =Table1[[#This Row],[Date]]/365.25+1900 -> 2004.0849 | C11: =Table1[[#This Row],[Year]]-$B$6 -> 2.3353867 | D11: 1598.9098 | E11: 28780376 | F11: =VLOOKUP(A11+1,CPI!$A$2:$B$956,2,FALSE) -> 186.7 | G11: =E11/F11*$F$84 -> 49663337 | H11: =_xlfn.XMATCH(Table1[[#This Row],[Date]]+1+Year_span*365.25,Table1[Date],-1,1) -> 18 | I11: {=-LN(INDEX(Table1[Cost deflated],Table1[[#This Row],[Row for X years later]])/Table1[[#This Row],[Cost deflated]])/(INDEX(Table1[Date],Table1[[#This Row],[Row for X years later]])-Table1[[#This Row],[Date]])*365.25/4} -> 0.10062529 | J11: =Table1[[#This Row],[Cost deflated]]/$G$6*100 -> 28.738926
A12: 38107 | B12: =Table1[[#This Row],[Date]]/365.25+1900 -> 2004.3313 | C12: =Table1[[#This Row],[Year]]-$B$6 -> 2.5817933 | D12: 1135.6987 | E12: 20442576 | F12: =VLOOKUP(A12+1,CPI!$A$2:$B$956,2,FALSE) -> 188.2 | G12: =E12/F12*$F$84 -> 34994497 | H12: =_xlfn.XMATCH(Table1[[#This Row],[Date]]+1+Year_span*365.25,Table1[Date],-1,1) -> 19 | I12: {=-LN(INDEX(Table1[Cost deflated],Table1[[#This Row],[Row for X years later]])/Table1[[#This Row],[Cost deflated]])/(INDEX(Table1[Date],Table1[[#This Row],[Row for X years later]])-Table1[[#This Row],[Date]])*365.25/4} -> 0.075819858 | J12: =Table1[[#This Row],[Cost deflated]]/$G$6*100 -> 20.250436
A13: 38199 | B13: =Table1[[#This Row],[Date]]/365.25+1900 -> 2004.5832 | C13: =Table1[[#This Row],[Year]]-$B$6 -> 2.8336756 | D13: 1107.4637 | E13: 19934346 | F13: =VLOOKUP(A13+1,CPI!$A$2:$B$956,2,FALSE) -> 189.2 | G13: =E13/F13*$F$84 -> 33944124 | H13: =_xlfn.XMATCH(Table1[[#This Row],[Date]]+1+Year_span*365.25,Table1[Date],-1,1) -> 20 | I13: {=-LN(INDEX(Table1[Cost deflated],Table1[[#This Row],[Row for X years later]])/Table1[[#This Row],[Cost deflated]])/(INDEX(Table1[Date],Table1[[#This Row],[Row for X years later]])-Table1[[#This Row],[Date]])*365.25/4} -> 0.074755886 | J13: =Table1[[#This Row],[Cost deflated]]/$G$6*100 -> 19.642612
A14: 38291 | B14: =Table1[[#This Row],[Date]]/365.25+1900 -> 2004.835 | C14: =Table1[[#This Row],[Year]]-$B$6 -> 3.0855578 | D14: 1028.8507 | E14: 18519312 | F14: =VLOOKUP(A14+1,CPI!$A$2:$B$956,2,FALSE) -> 191.7 | G14: =E14/F14*$F$84 -> 31123361 | H14: =_xlfn.XMATCH(Table1[[#This Row],[Date]]+1+Year_span*365.25,Table1[Date],-1,1) -> 21 | I14: {=-LN(INDEX(Table1[Cost deflated],Table1[[#This Row],[Row for X years later]])/Table1[[#This Row],[Cost deflated]])/(INDEX(Table1[Date],Table1[[#This Row],[Row for X years later]])-Table1[[#This Row],[Date]])*365.25/4} -> 0.087324846 | J14: =Table1[[#This Row],[Cost deflated]]/$G$6*100 -> 18.010307
A15: 38383 | B15: =Table1[[#This Row],[Date]]/365.25+1900 -> 2005.0869 | C15: =Table1[[#This Row],[Year]]-$B$6 -> 3.3374401 | D15: 974.16498 | E15: 17534970 | F15: =VLOOKUP(A15+1,CPI!$A$2:$B$956,2,FALSE) -> 192.4 | G15: =E15/F15*$F$84 -> 29361869 | H15: =_xlfn.XMATCH(Table1[[#This Row],[Date]]+1+Year_span*365.25,Table1[Date],-1,1) -> 22 | I15: {=-LN(INDEX(Table1[Cost deflated],Table1[[#This Row],[Row for X years later]])/Table1[[#This Row],[Cost deflated]])/(INDEX(Table1[Date],Table1[[#This Row],[Row for X years later]])-Table1[[#This Row],[Date]])*365.25/4} -> 0.15383694 | J15: =Table1[[#This Row],[Cost deflated]]/$G$6*100 -> 16.990976
A16: 38472 | B16: =Table1[[#This Row],[Date]]/365.25+1900 -> 2005.3306 | C16: =Table1[[#This Row],[Year]]-$B$6 -> 3.5811088 | D16: 897.76108 | E16: 16159699 | F16: =VLOOKUP(A16+1,CPI!$A$2:$B$956,2,FALSE) -> 193.6 | G16: =E16/F16*$F$84 -> 26891292 | H16: =_xlfn.XMATCH(Table1[[#This Row],[Date]]+1+Year_span*365.25,Table1[Date],-1,1) -> 23 | I16: {=-LN(INDEX(Table1[Cost deflated],Table1[[#This Row],[Row for X years later]])/Table1[[#This Row],[Cost deflated]])/(INDEX(Table1[Date],Table1[[#This Row],[Row for X years later]])-Table1[[#This Row],[Date]])*365.25/4} -> 0.21545252 | J16: =Table1[[#This Row],[Cost deflated]]/$G$6*100 -> 15.561315
A17: 38564 | B17: =Table1[[#This Row],[Date]]/365.25+1900 -> 2005.5825 | C17: =Table1[[#This Row],[Year]]-$B$6 -> 3.8329911 | D17: 898.90134 | E17: 16180224 | F17: =VLOOKUP(A17+1,CPI!$A$2:$B$956,2,FALSE) -> 196.1 | G17: =E17/F17*$F$84 -> 26582186 | H17: =_xlfn.XMATCH(Table1[[#This Row],[Date]]+1+Year_span*365.25,Table1[Date],-1,1) -> 24 | I17: {=-LN(INDEX(Table1[Cost deflated],Table1[[#This Row],[Row for X years later]])/Table1[[#This Row],[Cost deflated]])/(INDEX(Table1[Date],Table1[[#This Row],[Row for X years later]])-Table1[[#This Row],[Date]])*365.25/4} -> 0.26475067 | J17: =Table1[[#This Row],[Cost deflated]]/$G$6*100 -> 15.382443
A18: 38656 | B18: =Table1[[#This Row],[Date]]/365.25+1900 -> 2005.8344 | C18: =Table1[[#This Row],[Year]]-$B$6 -> 4.0848734 | D18: 766.72912 | E18: 13801124 | F18: =VLOOKUP(A18+1,CPI!$A$2:$B$956,2,FALSE) -> 198.1 | G18: =E18/F18*$F$84 -> 22444697 | H18: =_xlfn.XMATCH(Table1[[#This Row],[Date]]+1+Year_span*365.25,Table1[Date],-1,1) -> 25 | I18: {=-LN(INDEX(Table1[Cost deflated],Table1[[#This Row],[Row for X years later]])/Table1[[#This Row],[Cost deflated]])/(INDEX(Table1[Date],Table1[[#This Row],[Row for X years later]])-Table1[[#This Row],[Date]])*365.25/4} -> 0.31405051 | J18: =Table1[[#This Row],[Cost deflated]]/$G$6*100 -> 12.988182
... A41: 40755 | B41: =Table1[[#This Row],[Date]]/365.25+1900 -> 2011.5811 | C41: =Table1[[#This Row],[Year]]-$B$6 -> 9.8316222 | D41: 0.1166326 | E41: 10496.934 | F41: =VLOOKUP(A41+1,CPI!$A$2:$B$956,2,FALSE) -> 226.106 | G41: =E41/F41*$F$84 -> 14956.643 | H41: =_xlfn.XMATCH(Table1[[#This Row],[Date]]+1+Year_span*365.25,Table1[Date],-1,1) -> 48 | I41: {=-LN(INDEX(Table1[Cost deflated],Table1[[#This Row],[Row for X years later]])/Table1[[#This Row],[Cost deflated]])/(INDEX(Table1[Date],Table1[[#This Row],[Row for X years later]])-Table1[[#This Row],[Date]])*365.25/4} -> 0.067472485 | J41: =Table1[[#This Row],[Cost deflated]]/$G$6*100 -> 0.0086550336
A42: 40846 | B42: =Table1[[#This Row],[Date]]/365.25+1900 -> 2011.8303 | C42: =Table1[[#This Row],[Year]]-$B$6 -> 10.080767 | D42: 0.086038201 | E42: 7743.4381 | F42: =VLOOKUP(A42+2,CPI!$A$2:$B$956,2,FALSE) -> 227.169 | G42: =E42/F42*$F$84 -> 10981.673 | H42: =_xlfn.XMATCH(Table1[[#This Row],[Date]]+1+Year_span*365.25,Table1[Date],-1,1) -> 48 | I42: {=-LN(INDEX(Table1[Cost deflated],Table1[[#This Row],[Row for X years later]])/Table1[[#This Row],[Cost deflated]])/(INDEX(Table1[Date],Table1[[#This Row],[Row for X years later]])-Table1[[#This Row],[Date]])*365.25/4} -> 0.045513313 | J42: =Table1[[#This Row],[Cost deflated]]/$G$6*100 -> 0.0063548184
A43: 40939 | B43: =Table1[[#This Row],[Date]]/365.25+1900 -> 2012.0849 | C43: =Table1[[#This Row],[Year]]-$B$6 -> 10.335387 | D43: 0.085180212 | E43: 7666.219 | F43: =VLOOKUP(A43+1,CPI!$A$2:$B$956,2,FALSE) -> 228.329 | G43: =E43/F43*$F$84 -> 10816.927 | H43: =_xlfn.XMATCH(Table1[[#This Row],[Date]]+1+Year_span*365.25,Table1[Date],-1,1) -> 50 | I43: {=-LN(INDEX(Table1[Cost deflated],Table1[[#This Row],[Row for X years later]])/Table1[[#This Row],[Cost deflated]])/(INDEX(Table1[Date],Table1[[#This Row],[Row for X years later]])-Table1[[#This Row],[Date]])*365.25/4} -> 0.057349458 | J43: =Table1[[#This Row],[Cost deflated]]/$G$6*100 -> 0.0062594839
A44: 41029 | B44: =Table1[[#This Row],[Date]]/365.25+1900 -> 2012.3313 | C44: =Table1[[#This Row],[Year]]-$B$6 -> 10.581793 | D44: 0.065569918 | E44: 5901.2926 | F44: =VLOOKUP(A44+1,CPI!$A$2:$B$956,2,FALSE) -> 228.713 | G44: =E44/F44*$F$84 -> 8312.6606 | H44: =_xlfn.XMATCH(Table1[[#This Row],[Date]]+1+Year_span*365.25,Table1[Date],-1,1) -> 51 | I44: {=-LN(INDEX(Table1[Cost deflated],Table1[[#This Row],[Row for X years later]])/Table1[[#This Row],[Cost deflated]])/(INDEX(Table1[Date],Table1[[#This Row],[Row for X years later]])-Table1[[#This Row],[Date]])*365.25/4} -> 0.03111448 | J44: =Table1[[#This Row],[Cost deflated]]/$G$6*100 -> 0.0048103279
A45: 41121 | B45: =Table1[[#This Row],[Date]]/365.25+1900 -> 2012.5832 | C45: =Table1[[#This Row],[Year]]-$B$6 -> 10.833676 | D45: 0.066496904 | E45: 5984.7213 | F45: =VLOOKUP(A45+1,CPI!$A$2:$B$956,2,FALSE) -> 229.918 | G45: =E45/F45*$F$84 -> 8385.9971 | H45: =_xlfn.XMATCH(Table1[[#This Row],[Date]]+1+Year_span*365.25,Table1[Date],-1,1) -> 52 | I45: {=-LN(INDEX(Table1[Cost deflated],Table1[[#This Row],[Row for X years later]])/Table1[[#This Row],[Cost deflated]])/(INDEX(Table1[Date],Table1[[#This Row],[Row for X years later]])-Table1[[#This Row],[Date]])*365.25/4} -> 0.12625575 | J45: =Table1[[#This Row],[Cost deflated]]/$G$6*100 -> 0.0048527659
A46: 41213 | B46: =Table1[[#This Row],[Date]]/365.25+1900 -> 2012.835 | C46: =Table1[[#This Row],[Year]]-$B$6 -> 11.085558 | D46: 0.073537214 | E46: 6618.3493 | F46: =VLOOKUP(A46+1,CPI!$A$2:$B$956,2,FALSE) -> 231.249 | G46: =E46/F46*$F$84 -> 9220.4808 | H46: =_xlfn.XMATCH(Table1[[#This Row],[Date]]+1+Year_span*365.25,Table1[Date],-1,1) -> 53 | I46: {=-LN(INDEX(Table1[Cost deflated],Table1[[#This Row],[Row for X years later]])/Table1[[#This Row],[Cost deflated]])/(INDEX(Table1[Date],Table1[[#This Row],[Row for X years later]])-Table1[[#This Row],[Date]])*365.25/4} -> 0.14170612 | J46: =Table1[[#This Row],[Cost deflated]]/$G$6*100 -> 0.0053356606
A47: 41305 | B47: =Table1[[#This Row],[Date]]/365.25+1900 -> 2013.0869 | C47: =Table1[[#This Row],[Year]]-$B$6 -> 11.33744 | D47: 0.063014956 | E47: 5671.3461 | F47: =VLOOKUP(A47+1,CPI!$A$2:$B$956,2,FALSE) -> 232.937 | G47: =E47/F47*$F$84 -> 7843.8887 | H47: =_xlfn.XMATCH(Table1[[#This Row],[Date]]+1+Year_span*365.25,Table1[Date],-1,1) -> 53 | I47: {=-LN(INDEX(Table1[Cost deflated],Table1[[#This Row],[Row for X years later]])/Table1[[#This Row],[Cost deflated]])/(INDEX(Table1[Date],Table1[[#This Row],[Row for X years later]])-Table1[[#This Row],[Date]])*365.25/4} -> 0.1399837 | J47: =Table1[[#This Row],[Cost deflated]]/$G$6*100 -> 0.0045390613
A48: 41394 | B48: =Table1[[#This Row],[Date]]/365.25+1900 -> 2013.3306 | C48: =Table1[[#This Row],[Year]]-$B$6 -> 11.581109 | D48: 0.063641248 | E48: 5550.2648 | F48: =VLOOKUP(A48+1,CPI!$A$2:$B$956,2,FALSE) -> 231.893 | G48: =E48/F48*$F$84 -> 7710.9843 | H48: =_xlfn.XMATCH(Table1[[#This Row],[Date]]+1+Year_span*365.25,Table1[Date],-1,1) -> 53 | I48: {=-LN(INDEX(Table1[Cost deflated],Table1[[#This Row],[Row for X years later]])/Table1[[#This Row],[Cost deflated]])/(INDEX(Table1[Date],Table1[[#This Row],[Row for X years later]])-Table1[[#This Row],[Date]])*365.25/4} -> 0.15190725 | J48: =Table1[[#This Row],[Cost deflated]]/$G$6*100 -> 0.0044621529
A49: 41486 | B49: =Table1[[#This Row],[Date]]/365.25+1900 -> 2013.5825 | C49: =Table1[[#This Row],[Year]]-$B$6 -> 11.832991 | D49: 0.061669609 | E49: 5550.2648 | F49: =VLOOKUP(A49+1,CPI!$A$2:$B$956,2,FALSE) -> 233.456 | G49: =E49/F49*$F$84 -> 7659.3588 | H49: =_xlfn.XMATCH(Table1[[#This Row],[Date]]+1+Year_span*365.25,Table1[Date],-1,1) -> 54 | I49: {=-LN(INDEX(Table1[Cost deflated],Table1[[#This Row],[Row for X years later]])/Table1[[#This Row],[Cost deflated]])/(INDEX(Table1[Date],Table1[[#This Row],[Row for X years later]])-Table1[[#This Row],[Date]])*365.25/4} -> 0.1394403 | J49: =Table1[[#This Row],[Cost deflated]]/$G$6*100 -> 0.0044322785
A50: 41578 | B50: =Table1[[#This Row],[Date]]/365.25+1900 -> 2013.8344 | C50: =Table1[[#This Row],[Year]]-$B$6 -> 12.084873 | D50: 0.056623078 | E50: 5096.077 | F50: =VLOOKUP(A50+1,CPI!$A$2:$B$956,2,FALSE) -> 234.1 | G50: =E50/F50*$F$84 -> 7013.2338 | H50: =_xlfn.XMATCH(Table1[[#This Row],[Date]]+1+Year_span*365.25,Table1[Date],-1,1) -> 55 | I50: {=-LN(INDEX(Table1[Cost deflated],Table1[[#This Row],[Row for X years later]])/Table1[[#This Row],[Cost deflated]])/(INDEX(Table1[Date],Table1[[#This Row],[Row for X years later]])-Table1[[#This Row],[Date]])*365.25/4} -> 0.11007066 | J50: =Table1[[#This Row],[Cost deflated]]/$G$6*100 -> 0.0040583822
A51: 41670 | B51: =Table1[[#This Row],[Date]]/365.25+1900 -> 2014.0862 | C51: =Table1[[#This Row],[Year]]-$B$6 -> 12.336756 | D51: 0.044534522 | E51: 4008.107 | F51: =VLOOKUP(A51+1,CPI!$A$2:$B$956,2,FALSE) -> 235.547 | G51: =E51/F51*$F$84 -> 5482.0814 | H51: =_xlfn.XMATCH(Table1[[#This Row],[Date]]+1+Year_span*365.25,Table1[Date],-1,1) -> 56 | I51: {=-LN(INDEX(Table1[Cost deflated],Table1[[#This Row],[Row for X years later]])/Table1[[#This Row],[Cost deflated]])/(INDEX(Table1[Date],Table1[[#This Row],[Row for X years later]])-Table1[[#This Row],[Date]])*365.25/4} -> 0.098341141 | J51: =Table1[[#This Row],[Cost deflated]]/$G$6*100 -> 0.0031723428
A52: 41759 | B52: =Table1[[#This Row],[Date]]/365.25+1900 -> 2014.3299 | C52: =Table1[[#This Row],[Year]]-$B$6 -> 12.580424 | D52: 0.054672187 | E52: 4920.4968 | F52: =VLOOKUP(A52+1,CPI!$A$2:$B$956,2,FALSE) -> 236.918 | G52: =E52/F52*$F$84 -> 6691.0557 | H52: =_xlfn.XMATCH(Table1[[#This Row],[Date]]+1+Year_span*365.25,Table1[Date],-1,1) -> 57 | I52: {=-LN(INDEX(Table1[Cost deflated],Table1[[#This Row],[Row for X years later]])/Table1[[#This Row],[Cost deflated]])/(INDEX(Table1[Date],Table1[[#This Row],[Row for X years later]])-Table1[[#This Row],[Date]])*365.25/4} -> 0.14179054 | J52: =Table1[[#This Row],[Cost deflated]]/$G$6*100 -> 0.0038719459
A53: 41851 | B53: =Table1[[#This Row],[Date]]/365.25+1900 -> 2014.5818 | C53: =Table1[[#This Row],[Year]]-$B$6 -> 12.832307 | D53: 0.054498302 | E53: 4904.8472 | F53: =VLOOKUP(A53+1,CPI!$A$2:$B$956,2,FALSE) -> 237.46 | G53: =E53/F53*$F$84 -> 6654.5511 | H53: =_xlfn.XMATCH(Table1[[#This Row],[Date]]+1+Year_span*365.25,Table1[Date],-1,1) -> 58 | I53: {=-LN(INDEX(Table1[Cost deflated],Table1[[#This Row],[Row for X years later]])/Table1[[#This Row],[Cost deflated]])/(INDEX(Table1[Date],Table1[[#This Row],[Row for X years later]])-Table1[[#This Row],[Date]])*365.25/4} -> 0.11736779 | J53: =Table1[[#This Row],[Cost deflated]]/$G$6*100 -> 0.0038508216
A54: 41943 | B54: =Table1[[#This Row],[Date]]/365.25+1900 -> 2014.8337 | C54: =Table1[[#This Row],[Year]]-$B$6 -> 13.084189 | D54: 0.063676561 | E54: 5730.8905 | F54: =VLOOKUP(A54+1,CPI!$A$2:$B$956,2,FALSE) -> 236.983 | G54: =E54/F54*$F$84 -> 7790.9186 | H54: =_xlfn.XMATCH(Table1[[#This Row],[Date]]+1+Year_span*365.25,Table1[Date],-1,1) -> 59 | I54: {=-LN(INDEX(Table1[Cost deflated],Table1[[#This Row],[Row for X years later]])/Table1[[#This Row],[Cost deflated]])/(INDEX(Table1[Date],Table1[[#This Row],[Row for X years later]])-Table1[[#This Row],[Date]])*365.25/4} -> 0.14638813 | J54: =Table1[[#This Row],[Cost deflated]]/$G$6*100 -> 0.0045084089
... A70: 43524 | B70: =Table1[[#This Row],[Date]]/365.25+1900 -> 2019.1622 | C70: =Table1[[#This Row],[Year]]-$B$6 -> 17.412731 | D70: 0.011034843 | E70: 993.13587 | F70: =VLOOKUP(A70+1,CPI!$A$2:$B$956,2,FALSE) -> 254.277 | G70: =E70/F70*$F$84 -> 1258.3033 | H70: =_xlfn.XMATCH(Table1[[#This Row],[Date]]+1+Year_span*365.25,Table1[Date],-1,1) -> 77 | I70: {=-LN(INDEX(Table1[Cost deflated],Table1[[#This Row],[Row for X years later]])/Table1[[#This Row],[Cost deflated]])/(INDEX(Table1[Date],Table1[[#This Row],[Row for X years later]])-Table1[[#This Row],[Date]])*365.25/4} -> 0.063451193 | J70: =Table1[[#This Row],[Cost deflated]]/$G$6*100 -> 0.00072814851
A71: 43586 | B71: =Table1[[#This Row],[Date]]/365.25+1900 -> 2019.332 | C71: =Table1[[#This Row],[Year]]-$B$6 -> 17.582478 | D71: 0.0067368508 | E71: 606.31657 | F71: =VLOOKUP(A71,CPI!$A$2:$B$956,2,FALSE) -> 255.296 | G71: =E71/F71*$F$84 -> 765.13695 | H71: =_xlfn.XMATCH(Table1[[#This Row],[Date]]+1+Year_span*365.25,Table1[Date],-1,1) -> 77 | I71: {=-LN(INDEX(Table1[Cost deflated],Table1[[#This Row],[Row for X years later]])/Table1[[#This Row],[Cost deflated]])/(INDEX(Table1[Date],Table1[[#This Row],[Row for X years later]])-Table1[[#This Row],[Date]])*365.25/4} -> 0.023324724 | J71: =Table1[[#This Row],[Cost deflated]]/$G$6*100 -> 0.00044276553
A72: 43678 | B72: =Table1[[#This Row],[Date]]/365.25+1900 -> 2019.5838 | C72: =Table1[[#This Row],[Year]]-$B$6 -> 17.83436 | D72: 0.010468295 | E72: 942.14652 | F72: =VLOOKUP(A72,CPI!$A$2:$B$956,2,FALSE) -> 256.036 | G72: =E72/F72*$F$84 -> 1185.4989 | H72: =_xlfn.XMATCH(Table1[[#This Row],[Date]]+1+Year_span*365.25,Table1[Date],-1,1) -> 78 | I72: {=-LN(INDEX(Table1[Cost deflated],Table1[[#This Row],[Row for X years later]])/Table1[[#This Row],[Cost deflated]])/(INDEX(Table1[Date],Table1[[#This Row],[Row for X years later]])-Table1[[#This Row],[Date]])*365.25/4} -> 0.064200389 | J72: =Table1[[#This Row],[Cost deflated]]/$G$6*100 -> 0.00068601845
A73: 43799 | B73: =Table1[[#This Row],[Date]]/365.25+1900 -> 2019.9151 | C73: =Table1[[#This Row],[Year]]-$B$6 -> 18.16564 | D73: 0.0077263833 | E73: 695.3745 | F73: =VLOOKUP(A73+1,CPI!$A$2:$B$956,2,FALSE) -> 258.63 | G73: =E73/F73*$F$84 -> 866.21083 | H73: =_xlfn.XMATCH(Table1[[#This Row],[Date]]+1+Year_span*365.25,Table1[Date],-1,1) -> 78 | I73: {=-LN(INDEX(Table1[Cost deflated],Table1[[#This Row],[Row for X years later]])/Table1[[#This Row],[Cost deflated]])/(INDEX(Table1[Date],Table1[[#This Row],[Row for X years later]])-Table1[[#This Row],[Date]])*365.25/4} -> 0.041325511 | J73: =Table1[[#This Row],[Cost deflated]]/$G$6*100 -> 0.00050125445
A74: 43889 | B74: =Table1[[#This Row],[Date]]/365.25+1900 -> 2020.1615 | C74: =Table1[[#This Row],[Year]]-$B$6 -> 18.412047 | D74: 0.0071624043 | E74: 644.61638 | F74: =VLOOKUP(A74+2,CPI!$A$2:$B$956,2,FALSE) -> 258.076 | G74: =E74/F74*$F$84 -> 804.70643 | H74: =_xlfn.XMATCH(Table1[[#This Row],[Date]]+1+Year_span*365.25,Table1[Date],-1,1) -> 78 | I74: {=-LN(INDEX(Table1[Cost deflated],Table1[[#This Row],[Row for X years later]])/Table1[[#This Row],[Cost deflated]])/(INDEX(Table1[Date],Table1[[#This Row],[Row for X years later]])-Table1[[#This Row],[Date]])*365.25/4} -> 0.037673089 | J74: =Table1[[#This Row],[Cost deflated]]/$G$6*100 -> 0.00046566339
A75: 43982 | B75: =Table1[[#This Row],[Date]]/365.25+1900 -> 2020.4162 | C75: =Table1[[#This Row],[Year]]-$B$6 -> 18.666667 | D75: 0.0077951342 | E75: 701.56207 | F75: =VLOOKUP(A75+1,CPI!$A$2:$B$956,2,FALSE) -> 257.042 | G75: =E75/F75*$F$84 -> 879.31759 | H75: =_xlfn.XMATCH(Table1[[#This Row],[Date]]+1+Year_span*365.25,Table1[Date],-1,1) -> 78 | I75: {=-LN(INDEX(Table1[Cost deflated],Table1[[#This Row],[Row for X years later]])/Table1[[#This Row],[Cost deflated]])/(INDEX(Table1[Date],Table1[[#This Row],[Row for X years later]])-Table1[[#This Row],[Date]])*365.25/4} -> 0.053563706 | J75: =Table1[[#This Row],[Cost deflated]]/$G$6*100 -> 0.000508839
A76: 44074 | B76: =Table1[[#This Row],[Date]]/365.25+1900 -> 2020.668 | C76: =Table1[[#This Row],[Year]]-$B$6 -> 18.918549 | D76: 0.0076507291 | E76: 688.56562 | F76: =VLOOKUP(A76+1,CPI!$A$2:$B$956,2,FALSE) -> 259.997 | G76: =E76/F76*$F$84 -> 853.21945 | H76: =_xlfn.XMATCH(Table1[[#This Row],[Date]]+1+Year_span*365.25,Table1[Date],-1,1) -> 78 | J76: =Table1[[#This Row],[Cost deflated]]/$G$6*100 -> 0.00049373666
A77: 44165 | B77: =Table1[[#This Row],[Date]]/365.25+1900 -> 2020.9172 | C77: =Table1[[#This Row],[Year]]-$B$6 -> 19.167693 | D77: 0.005688542 | E77: 511.96878 | F77: =VLOOKUP(A77+1,CPI!$A$2:$B$956,2,FALSE) -> 262.045 | G77: =E77/F77*$F$84 -> 629.43567 | H77: =_xlfn.XMATCH(Table1[[#This Row],[Date]]+1+Year_span*365.25,Table1[Date],-1,1) -> 78 | J77: =Table1[[#This Row],[Cost deflated]]/$G$6*100 -> 0.00036423861
A78: 44255 | B78: =Table1[[#This Row],[Date]]/365.25+1900 -> 2021.1636 | C78: =Table1[[#This Row],[Year]]-$B$6 -> 19.4141 | D78: 0.0094537918 | E78: 850.84126 | F78: =VLOOKUP(A78+1,CPI!$A$2:$B$956,2,FALSE) -> 264.961 | G78: =E78/F78*$F$84 -> 1034.5473 | H78: =_xlfn.XMATCH(Table1[[#This Row],[Date]]+1+Year_span*365.25,Table1[Date],-1,1) -> 78 | J78: =Table1[[#This Row],[Cost deflated]]/$G$6*100 -> 0.00059866652
...

Sheet CPI
A1: observation_date | B1: CPIAUCSL | E1: BLS-based Index 1982-1984 = 100
A2: 17168 | B2: 21.48 | D2: 1774 | E2: 8.07
A3: 17199 | B3: 21.62 | D3: 1775 | E3: 7.654
A4: 17227 | B4: 22 | D4: 1776 | E4: 8.735
A5: 17258 | B5: 22 | D5: 1777 | E5: 10.649
A6: 17288 | B6: 21.95 | D6: 1778 | E6: 13.81
A7: 17319 | B7: 22.08 | D7: 1779 | E7: 12.23
A8: 17349 | B8: 22.23 | D8: 1780 | E8: 13.727
A9: 17380 | B9: 22.4 | D9: 1781 | E9: 11.065
A10: 17411 | B10: 22.84 | D10: 1782 | E10: 12.146
A11: 17441 | B11: 22.91 | D11: 1783 | E11: 10.649
A12: 17472 | B12: 23.06 | D12: 1784 | E12: 10.233
A13: 17502 | B13: 23.41 | D13: 1785 | E13: 9.734
... A231: 24139 | B231: 32.08 | D231: 2003 | E231: 184
A232: 24167 | B232: 32.18
A233: 24198 | B233: 32.28
A234: 24228 | B234: 32.35
A235: 24259 | B235: 32.38
A236: 24289 | B236: 32.45
A237: 24320 | B237: 32.65
A238: 24351 | B238: 32.75
A239: 24381 | B239: 32.85
A240: 24412 | B240: 32.88
A241: 24442 | B241: 32.92
A242: 24473 | B242: 32.9
A243: 24504 | B243: 33
... A946: 45901 | B946: 324.245
A947: 45931
A948: 45962 | B948: 325.063
A949: 45992 | B949: 326.031
A950: 46023 | B950: 326.588
A951: 46054 | B951: 327.46
A952: 46082 | B952: 330.293
A953: 46113 | B953: 332.407
A954: 46143 | B954: 333.979
A955: 46174 | B955: 332.568
A956: 46204 | B956: 332.813

Sheet Sources
A1: CPI monthly: https://fred.stlouisfed.org/series/CPIAUCSL
A2: CPI annual: Historical Statisics of the United States: Millennial Edition Online, https://hsus.cambridge.org/HSUSWeb/toc/treeTablePathIdCc1-2.html
A3: Electricity: https://archive.org/details/powerlossorigins0000hirs/page/48/mode/2up
A4: Illumination: https://ourworldindata.org/grapher/the-price-for-lighting-per-million-lumen-hours-in-the-uk-in-british-pound.csv?v=1&csvType=full&useColumnShortNames=true
A5: Compute: https://users.nber.org/~confer/2001/si2001/nordhaus.pdf
A6: Batteries: https://ourworldindata.org/grapher/price-of-lithium-ion-battery-cells.csv?v=1&csvType=full&useColumnShortNames=true
A7: DNA sequencing: https://www.genome.gov/sites/default/files/media/files/2023-05/Sequencing_Cost_Data_Table_May2022.xls
